<?xml version="1.0" ?>
<!-- Generated using onshape-to-robot -->
<!-- Onshape https://ricerobotics.onshape.com/documents/113d96fdef4adb1a3716524e/w/28f7dad7c74d67852509cca5/e/a5f92556bc33e188cf7c0d25 -->
<robot name="catbot">
    <!-- Link part_1 -->
    <link name="part_1">
        <inertial>
            <origin xyz="0 0 0" rpy="0 0 0"/>
            <mass value="1e-09"/>
            <inertia ixx="1e-09" ixy="0" ixz="0" iyy="1e-09" iyz="0" izz="1e-09"/>
        </inertial>
    </link>
    <!-- Link upper_link_1 -->
    <link name="upper_link_1">
        <inertial>
            <origin xyz="0 0 0" rpy="0 0 0"/>
            <mass value="1e-09"/>
            <inertia ixx="1e-09" ixy="0" ixz="0" iyy="1e-09" iyz="0" izz="1e-09"/>
        </inertial>
    </link>
    <!-- Link upper_link_2 -->
    <link name="upper_link_2">
        <inertial>
            <origin xyz="0 0 0" rpy="0 0 0"/>
            <mass value="1e-09"/>
            <inertia ixx="1e-09" ixy="0" ixz="0" iyy="1e-09" iyz="0" izz="1e-09"/>
        </inertial>
    </link>
    <!-- Frame closing_passive5_1 (dummy link + fixed joint) -->
    <link name="closing_passive5_1">
        <origin xyz="0 0 0" rpy="0 -0 0"/>
        <inertial>
            <origin xyz="0 0 0" rpy="0 0 0"/>
            <mass value="1e-9"/>
            <inertia ixx="0" ixy="0" ixz="0" iyy="0" iyz="0" izz="0"/>
        </inertial>
    </link>
    <joint name="closing_passive5_1_frame" type="fixed">
        <origin xyz="-6.64399e-16 -0.105 3.52948e-16" rpy="2.02456e-16 2.9476e-17 -1.5708"/>
        <parent link="upper_link_2"/>
        <child link="closing_passive5_1"/>
        <axis xyz="0 0 0"/>
    </joint>
    <!-- Link upper_link_2_grainger_35jc77 -->
    <link name="upper_link_2_grainger_35jc77">
        <inertial>
            <origin xyz="0 0 0" rpy="0 0 0"/>
            <mass value="1e-09"/>
            <inertia ixx="1e-09" ixy="0" ixz="0" iyy="1e-09" iyz="0" izz="1e-09"/>
        </inertial>
        <!-- Part grainger_35jc77 -->
        <visual>
            <origin xyz="-2.94903e-17 0 0" rpy="-1.2326e-32 -1.84889e-32 -5.55112e-17"/>
            <geometry>
                <mesh filename="package://catbot_pybullet/meshes/grainger_35jc77.stl"/>
            </geometry>
            <material name="grainger_35jc77_material">
                <color rgba="0.203922 0.203922 0.203922 1.0"/>
            </material>
        </visual>
        <collision>
            <origin xyz="-2.94903e-17 0 0" rpy="-1.2326e-32 -1.84889e-32 -5.55112e-17"/>
            <geometry>
                <mesh filename="package://catbot_pybullet/meshes/grainger_35jc77.stl"/>
            </geometry>
        </collision>
    </link>
    <!-- Joint from upper_link_2 to upper_link_2_grainger_35jc77 -->
    <joint name="upper_link_2_grainger_35jc77_fixed" type="fixed">
        <origin xyz="-1.21431e-17 0 -0.0091" rpy="8.30319e-17 -1.29878e-16 2.22045e-16"/>
        <parent link="upper_link_2"/>
        <child link="upper_link_2_grainger_35jc77"/>
        <axis xyz="0 0 1"/>
        <limit effort="10" velocity="10"/>
    </joint>
    <!-- Link upper_link_2_grainger_35jc77_2 -->
    <link name="upper_link_2_grainger_35jc77_2">
        <inertial>
            <origin xyz="0 0 0" rpy="0 0 0"/>
            <mass value="1e-09"/>
            <inertia ixx="1e-09" ixy="0" ixz="0" iyy="1e-09" iyz="0" izz="1e-09"/>
        </inertial>
        <!-- Part grainger_35jc77_2 -->
        <visual>
            <origin xyz="-1.38778e-17 0 0" rpy="0 -0 5.55112e-17"/>
            <geometry>
                <mesh filename="package://catbot_pybullet/meshes/grainger_35jc77.stl"/>
            </geometry>
            <material name="grainger_35jc77_2_material">
                <color rgba="0.203922 0.203922 0.203922 1.0"/>
            </material>
        </visual>
        <collision>
            <origin xyz="-1.38778e-17 0 0" rpy="0 -0 5.55112e-17"/>
            <geometry>
                <mesh filename="package://catbot_pybullet/meshes/grainger_35jc77.stl"/>
            </geometry>
        </collision>
    </link>
    <!-- Joint from upper_link_2 to upper_link_2_grainger_35jc77_2 -->
    <joint name="upper_link_2_grainger_35jc77_2_fixed" type="fixed">
        <origin xyz="-6.64399e-16 -0.105 -0.0091" rpy="-7.17371e-18 -9.17139e-17 -3.88578e-16"/>
        <parent link="upper_link_2"/>
        <child link="upper_link_2_grainger_35jc77_2"/>
        <axis xyz="0 0 1"/>
        <limit effort="10" velocity="10"/>
    </joint>
    <!-- Link upper_link_2_pins -->
    <link name="upper_link_2_pins">
        <inertial>
            <origin xyz="2.77556e-17 -0.0105 -6.56111e-18" rpy="0 0 0"/>
            <mass value="0.0115862"/>
            <inertia ixx="4.8246e-07" ixy="-3.20447e-39" ixz="2.67819e-23" iyy="1.29989e-07" iyz="6.74789e-39" izz="4.8246e-07"/>
        </inertial>
        <!-- Part pins -->
        <visual>
            <origin xyz="2.77556e-17 0 -6.93889e-18" rpy="6.16298e-33 -0 0"/>
            <geometry>
                <mesh filename="package://catbot_pybullet/meshes/pins.stl"/>
            </geometry>
            <material name="pins_material">
                <color rgba="0.498039 0.498039 0.498039 1.0"/>
            </material>
        </visual>
        <collision>
            <origin xyz="2.77556e-17 0 -6.93889e-18" rpy="6.16298e-33 -0 0"/>
            <geometry>
                <mesh filename="package://catbot_pybullet/meshes/pins.stl"/>
            </geometry>
        </collision>
    </link>
    <!-- Joint from upper_link_2 to upper_link_2_pins -->
    <joint name="upper_link_2_pins_fixed" type="fixed">
        <origin xyz="-6.64399e-16 -0.105 0.0014" rpy="1.5708 2.9476e-17 -1.5708"/>
        <parent link="upper_link_2"/>
        <child link="upper_link_2_pins"/>
        <axis xyz="0 0 1"/>
        <limit effort="10" velocity="10"/>
    </joint>
    <!-- Link upper_link_2_upper_link_2 -->
    <link name="upper_link_2_upper_link_2">
        <inertial>
            <origin xyz="9.80159e-18 -0.00357124 2.17453e-17" rpy="0 0 0"/>
            <mass value="0.0328541"/>
            <inertia ixx="3.65189e-06" ixy="-1.23455e-36" ixz="-4.57734e-21" iyy="4.27756e-05" iyz="1.0545e-36" izz="3.94031e-05"/>
        </inertial>
        <!-- Part upper_link_2 -->
        <visual>
            <origin xyz="2.77556e-17 0 1.73472e-17" rpy="2.46519e-32 5.55112e-17 -4.93038e-32"/>
            <geometry>
                <mesh filename="package://catbot_pybullet/meshes/upper_link_2.stl"/>
            </geometry>
            <material name="upper_link_2_material">
                <color rgba="1 1 1 1.0"/>
            </material>
        </visual>
        <collision>
            <origin xyz="2.77556e-17 0 1.73472e-17" rpy="2.46519e-32 5.55112e-17 -4.93038e-32"/>
            <geometry>
                <mesh filename="package://catbot_pybullet/meshes/upper_link_2.stl"/>
            </geometry>
        </collision>
    </link>
    <!-- Joint from upper_link_2 to upper_link_2_upper_link_2 -->
    <joint name="upper_link_2_upper_link_2_fixed" type="fixed">
        <origin xyz="-3.17454e-16 -0.0525 -0.00552876" rpy="1.5708 -1.5289e-16 -1.5708"/>
        <parent link="upper_link_2"/>
        <child link="upper_link_2_upper_link_2"/>
        <axis xyz="0 0 1"/>
        <limit effort="10" velocity="10"/>
    </joint>
    <!-- Link upper_link_2_pins_2 -->
    <link name="upper_link_2_pins_2">
        <inertial>
            <origin xyz="-1.38778e-17 -0.0105 3.77784e-19" rpy="0 0 0"/>
            <mass value="0.0115862"/>
            <inertia ixx="4.8246e-07" ixy="1.14314e-38" ixz="0" iyy="1.29989e-07" iyz="-1.5098e-38" izz="4.8246e-07"/>
        </inertial>
        <!-- Part pins_2 -->
        <visual>
            <origin xyz="-1.38778e-17 0 0" rpy="-2.46519e-32 5.55112e-17 3.69779e-32"/>
            <geometry>
                <mesh filename="package://catbot_pybullet/meshes/pins.stl"/>
            </geometry>
            <material name="pins_2_material">
                <color rgba="0.498039 0.498039 0.498039 1.0"/>
            </material>
        </visual>
        <collision>
            <origin xyz="-1.38778e-17 0 0" rpy="-2.46519e-32 5.55112e-17 3.69779e-32"/>
            <geometry>
                <mesh filename="package://catbot_pybullet/meshes/pins.stl"/>
            </geometry>
        </collision>
    </link>
    <!-- Joint from upper_link_2 to upper_link_2_pins_2 -->
    <joint name="upper_link_2_pins_2_fixed" type="fixed">
        <origin xyz="-1.21431e-17 0 -0.0196" rpy="-1.5708 3.69779e-32 -5.55112e-17"/>
        <parent link="upper_link_2"/>
        <child link="upper_link_2_pins_2"/>
        <axis xyz="0 0 1"/>
        <limit effort="10" velocity="10"/>
    </joint>
    <!-- Joint from upper_link_1 to upper_link_2 -->
    <joint name="passive6" type="continuous">
        <origin xyz="8.32667e-17 -0.08 0.0298" rpy="8.7803e-17 1.71793e-16 2.10804"/>
        <parent link="upper_link_1"/>
        <child link="upper_link_2"/>
        <axis xyz="0 0 1"/>
        <limit effort="10" velocity="10"/>
        <joint_properties friction="0.0"/>
    </joint>
    <!-- Link upper_link_1_upper_link_1 -->
    <link name="upper_link_1_upper_link_1">
        <inertial>
            <origin xyz="0.00740119 -0.009 -0.000694539" rpy="0 0 0"/>
            <mass value="0.051287"/>
            <inertia ixx="6.73493e-06" ixy="1.38839e-14" ixz="-1.45044e-07" iyy="5.13983e-05" iyz="-1.39843e-15" izz="4.81368e-05"/>
        </inertial>
        <!-- Part upper_link_1 -->
        <visual>
            <origin xyz="0 0 0" rpy="0 -0 -3.8538e-33"/>
            <geometry>
                <mesh filename="package://catbot_pybullet/meshes/upper_link_1.stl"/>
            </geometry>
            <material name="upper_link_1_material">
                <color rgba="0.972549 0.529412 0.00392157 1.0"/>
            </material>
        </visual>
        <collision>
            <origin xyz="0 0 0" rpy="0 -0 -3.8538e-33"/>
            <geometry>
                <mesh filename="package://catbot_pybullet/meshes/upper_link_1.stl"/>
            </geometry>
        </collision>
    </link>
    <!-- Joint from upper_link_1 to upper_link_1_upper_link_1 -->
    <joint name="upper_link_1_upper_link_1_fixed" type="fixed">
        <origin xyz="8.32667e-17 -0.04 0.0297" rpy="1.5708 5.13253e-17 1.5708"/>
        <parent link="upper_link_1"/>
        <child link="upper_link_1_upper_link_1"/>
        <axis xyz="0 0 1"/>
        <limit effort="10" velocity="10"/>
    </joint>
    <!-- Link upper_link_1_d_shaft_upper_motor -->
    <link name="upper_link_1_d_shaft_upper_motor">
        <inertial>
            <origin xyz="-7.68708e-21 -0.00381957 -0.000101825" rpy="0 0 0"/>
            <mass value="0.0169769"/>
            <inertia ixx="1.49221e-06" ixy="0" ixz="0" iyy="1.88178e-07" iyz="-9.51745e-09" izz="1.49914e-06"/>
        </inertial>
        <!-- Part d_shaft_upper_motor -->
        <visual>
            <origin xyz="0 0 0" rpy="2.88143e-33 -0 0"/>
            <geometry>
                <mesh filename="package://catbot_pybullet/meshes/d_shaft_upper_motor.stl"/>
            </geometry>
            <material name="d_shaft_upper_motor_material">
                <color rgba="0.498039 0.498039 0.498039 1.0"/>
            </material>
        </visual>
        <collision>
            <origin xyz="0 0 0" rpy="2.88143e-33 -0 0"/>
            <geometry>
                <mesh filename="package://catbot_pybullet/meshes/d_shaft_upper_motor.stl"/>
            </geometry>
        </collision>
    </link>
    <!-- Joint from upper_link_1 to upper_link_1_d_shaft_upper_motor -->
    <joint name="upper_link_1_d_shaft_upper_motor_fixed" type="fixed">
        <origin xyz="0 0 0.0117" rpy="-1.5708 -0 0"/>
        <parent link="upper_link_1"/>
        <child link="upper_link_1_d_shaft_upper_motor"/>
        <axis xyz="0 0 1"/>
        <limit effort="10" velocity="10"/>
    </joint>
    <!-- Joint from part_1 to upper_link_1 -->
    <joint name="motor1" type="revolute">
        <origin xyz="-0.0728365 0.0296822 0.227745" rpy="1.5708 1.5708 0"/>
        <parent link="part_1"/>
        <child link="upper_link_1"/>
        <axis xyz="0 0 1"/>
        <limit effort="50" velocity="50" lower="-0.780544" upper="1.96935"/>
        <joint_properties friction="0.0"/>
    </joint>
    <!-- Link lower_to_upper_thigh_connector -->
    <link name="lower_to_upper_thigh_connector">
        <inertial>
            <origin xyz="0 0 0" rpy="0 0 0"/>
            <mass value="1e-09"/>
            <inertia ixx="1e-09" ixy="0" ixz="0" iyy="1e-09" iyz="0" izz="1e-09"/>
        </inertial>
    </link>
    <!-- Link lower_thigh -->
    <link name="lower_thigh">
        <inertial>
            <origin xyz="0 0 0" rpy="0 0 0"/>
            <mass value="1e-09"/>
            <inertia ixx="1e-09" ixy="0" ixz="0" iyy="1e-09" iyz="0" izz="1e-09"/>
        </inertial>
    </link>
    <!-- Frame closing_passive3_2 (dummy link + fixed joint) -->
    <link name="closing_passive3_2">
        <origin xyz="0 0 0" rpy="0 -0 0"/>
        <inertial>
            <origin xyz="0 0 0" rpy="0 0 0"/>
            <mass value="1e-9"/>
            <inertia ixx="0" ixy="0" ixz="0" iyy="0" iyz="0" izz="0"/>
        </inertial>
    </link>
    <joint name="closing_passive3_2_frame" type="fixed">
        <origin xyz="0.000192277 -0.225 -2.24091e-16" rpy="3.14159 -1.26729e-15 1.57165"/>
        <parent link="lower_thigh"/>
        <child link="closing_passive3_2"/>
        <axis xyz="0 0 0"/>
    </joint>
    <!-- Link lower_thigh_lower_thigh -->
    <link name="lower_thigh_lower_thigh">
        <inertial>
            <origin xyz="-4.71887e-17 -0.009 1.42786e-17" rpy="0 0 0"/>
            <mass value="0.135358"/>
            <inertia ixx="1.79506e-05" ixy="6.83199e-36" ixz="9.9646e-22" iyy="0.000572228" iyz="1.39025e-35" izz="0.000563951"/>
        </inertial>
        <!-- Part lower_thigh -->
        <visual>
            <origin xyz="0 -3.38813e-21 1.38778e-17" rpy="0 -5.55112e-17 -1.2326e-32"/>
            <geometry>
                <mesh filename="package://catbot_pybullet/meshes/lower_thigh.stl"/>
            </geometry>
            <material name="lower_thigh_material">
                <color rgba="1 1 1 1.0"/>
            </material>
        </visual>
        <collision>
            <origin xyz="0 -3.38813e-21 1.38778e-17" rpy="0 -5.55112e-17 -1.2326e-32"/>
            <geometry>
                <mesh filename="package://catbot_pybullet/meshes/lower_thigh.stl"/>
            </geometry>
        </collision>
    </link>
    <!-- Joint from lower_thigh to lower_thigh_lower_thigh -->
    <joint name="lower_thigh_lower_thigh_fixed" type="fixed">
        <origin xyz="9.61386e-05 -0.1125 0.0001" rpy="-1.5708 1.26729e-15 -1.56994"/>
        <parent link="lower_thigh"/>
        <child link="lower_thigh_lower_thigh"/>
        <axis xyz="0 0 1"/>
        <limit effort="10" velocity="10"/>
    </joint>
    <!-- Joint from lower_to_upper_thigh_connector to lower_thigh -->
    <joint name="passive1" type="continuous">
        <origin xyz="-0.000995748 -0.060184 0.0315252" rpy="3.14159 -6.63175e-16 1.55604"/>
        <parent link="lower_to_upper_thigh_connector"/>
        <child link="lower_thigh"/>
        <axis xyz="0 0 1"/>
        <limit effort="10" velocity="10"/>
        <joint_properties friction="0.0"/>
    </joint>
    <!-- Link upper_thigh -->
    <link name="upper_thigh">
        <inertial>
            <origin xyz="0 0 0" rpy="0 0 0"/>
            <mass value="1e-09"/>
            <inertia ixx="1e-09" ixy="0" ixz="0" iyy="1e-09" iyz="0" izz="1e-09"/>
        </inertial>
    </link>
    <!-- Frame closing_passive5_2 (dummy link + fixed joint) -->
    <link name="closing_passive5_2">
        <origin xyz="0 0 0" rpy="0 -0 0"/>
        <inertial>
            <origin xyz="0 0 0" rpy="0 0 0"/>
            <mass value="1e-9"/>
            <inertia ixx="0" ixy="0" ixz="0" iyy="0" iyz="0" izz="0"/>
        </inertial>
    </link>
    <joint name="closing_passive5_2_frame" type="fixed">
        <origin xyz="-0.17998 -0.00265599 -0.0262503" rpy="-3.14159 -8.56631e-16 1.58555"/>
        <parent link="upper_thigh"/>
        <child link="closing_passive5_2"/>
        <axis xyz="0 0 0"/>
    </joint>
    <!-- Link shin -->
    <link name="shin">
        <inertial>
            <origin xyz="0 0 0" rpy="0 0 0"/>
            <mass value="1e-09"/>
            <inertia ixx="1e-09" ixy="0" ixz="0" iyy="1e-09" iyz="0" izz="1e-09"/>
        </inertial>
    </link>
    <!-- Frame closing_passive3_1 (dummy link + fixed joint) -->
    <link name="closing_passive3_1">
        <origin xyz="0 0 0" rpy="0 -0 0"/>
        <inertial>
            <origin xyz="0 0 0" rpy="0 0 0"/>
            <mass value="1e-9"/>
            <inertia ixx="0" ixy="0" ixz="0" iyy="0" iyz="0" izz="0"/>
        </inertial>
    </link>
    <joint name="closing_passive3_1_frame" type="fixed">
        <origin xyz="-0.06 -7.63278e-17 -1.14478e-16" rpy="1.07493e-16 3.1225e-16 -1.5708"/>
        <parent link="shin"/>
        <child link="closing_passive3_1"/>
        <axis xyz="0 0 0"/>
    </joint>
    <!-- Link shin_grainger_35jc77_6 -->
    <link name="shin_grainger_35jc77_6">
        <inertial>
            <origin xyz="0 0 0" rpy="0 0 0"/>
            <mass value="1e-09"/>
            <inertia ixx="1e-09" ixy="0" ixz="0" iyy="1e-09" iyz="0" izz="1e-09"/>
        </inertial>
        <!-- Part grainger_35jc77_6 -->
        <visual>
            <origin xyz="1.38778e-17 1.38778e-17 -1.73472e-18" rpy="-2.46519e-32 -0 -5.55112e-17"/>
            <geometry>
                <mesh filename="package://catbot_pybullet/meshes/grainger_35jc77.stl"/>
            </geometry>
            <material name="grainger_35jc77_6_material">
                <color rgba="0.203922 0.203922 0.203922 1.0"/>
            </material>
        </visual>
        <collision>
            <origin xyz="1.38778e-17 1.38778e-17 -1.73472e-18" rpy="-2.46519e-32 -0 -5.55112e-17"/>
            <geometry>
                <mesh filename="package://catbot_pybullet/meshes/grainger_35jc77.stl"/>
            </geometry>
        </collision>
    </link>
    <!-- Joint from shin to shin_grainger_35jc77_6 -->
    <joint name="shin_grainger_35jc77_6_fixed" type="fixed">
        <origin xyz="-0.06 -7.63278e-17 -0.0091" rpy="-3.1225e-16 7.97973e-17 3.14159"/>
        <parent link="shin"/>
        <child link="shin_grainger_35jc77_6"/>
        <axis xyz="0 0 1"/>
        <limit effort="10" velocity="10"/>
    </joint>
    <!-- Link shin_pins_4 -->
    <link name="shin_pins_4">
        <inertial>
            <origin xyz="1.38778e-17 -0.0105 3.77784e-19" rpy="0 0 0"/>
            <mass value="0.0115862"/>
            <inertia ixx="4.8246e-07" ixy="3.20447e-39" ixz="-2.67819e-23" iyy="1.29989e-07" iyz="-6.40894e-39" izz="4.8246e-07"/>
        </inertial>
        <!-- Part pins_4 -->
        <visual>
            <origin xyz="1.38778e-17 0 0" rpy="-4.93038e-32 -0 0"/>
            <geometry>
                <mesh filename="package://catbot_pybullet/meshes/pins.stl"/>
            </geometry>
            <material name="pins_4_material">
                <color rgba="0.498039 0.498039 0.498039 1.0"/>
            </material>
        </visual>
        <collision>
            <origin xyz="1.38778e-17 0 0" rpy="-4.93038e-32 -0 0"/>
            <geometry>
                <mesh filename="package://catbot_pybullet/meshes/pins.stl"/>
            </geometry>
        </collision>
    </link>
    <!-- Joint from shin to shin_pins_4 -->
    <joint name="shin_pins_4_fixed" type="fixed">
        <origin xyz="-0.06 -7.63278e-17 0.0014" rpy="1.5708 3.1225e-16 -1.5708"/>
        <parent link="shin"/>
        <child link="shin_pins_4"/>
        <axis xyz="0 0 1"/>
        <limit effort="10" velocity="10"/>
    </joint>
    <!-- Link shin_shin -->
    <link name="shin_shin">
        <inertial>
            <origin xyz="0.00749667 -0.00357124 3.17511e-08" rpy="0 0 0"/>
            <mass value="0.049659"/>
            <inertia ixx="5.3636e-06" ixy="7.11797e-36" ixz="1.12935e-10" iyy="0.00014437" iyz="2.18564e-13" izz="0.000139428"/>
        </inertial>
        <!-- Part shin -->
        <visual>
            <origin xyz="0 0 0" rpy="0 -0 0"/>
            <geometry>
                <mesh filename="package://catbot_pybullet/meshes/shin.stl"/>
            </geometry>
            <material name="shin_material">
                <color rgba="1 1 1 1.0"/>
            </material>
        </visual>
        <collision>
            <origin xyz="0 0 0" rpy="0 -0 0"/>
            <geometry>
                <mesh filename="package://catbot_pybullet/meshes/shin.stl"/>
            </geometry>
        </collision>
    </link>
    <!-- Joint from shin to shin_shin -->
    <joint name="shin_shin_fixed" type="fixed">
        <origin xyz="-0.08 -4.16334e-17 -0.0126712" rpy="-1.5708 1.37732e-16 -3.14159"/>
        <parent link="shin"/>
        <child link="shin_shin"/>
        <axis xyz="0 0 1"/>
        <limit effort="10" velocity="10"/>
    </joint>
    <!-- Link shin_pins_5 -->
    <link name="shin_pins_5">
        <inertial>
            <origin xyz="1.29422e-34 -0.0105 3.77784e-19" rpy="0 0 0"/>
            <mass value="0.0115862"/>
            <inertia ixx="4.8246e-07" ixy="2.21849e-38" ixz="0" iyy="1.29989e-07" iyz="5.94677e-39" izz="4.8246e-07"/>
        </inertial>
        <!-- Part pins_5 -->
        <visual>
            <origin xyz="0 0 0" rpy="0 -0 4.93038e-32"/>
            <geometry>
                <mesh filename="package://catbot_pybullet/meshes/pins.stl"/>
            </geometry>
            <material name="pins_5_material">
                <color rgba="0.498039 0.498039 0.498039 1.0"/>
            </material>
        </visual>
        <collision>
            <origin xyz="0 0 0" rpy="0 -0 4.93038e-32"/>
            <geometry>
                <mesh filename="package://catbot_pybullet/meshes/pins.stl"/>
            </geometry>
        </collision>
    </link>
    <!-- Joint from shin to shin_pins_5 -->
    <joint name="shin_pins_5_fixed" type="fixed">
        <origin xyz="0 0 0.0014" rpy="1.5708 -4.93038e-32 0"/>
        <parent link="shin"/>
        <child link="shin_pins_5"/>
        <axis xyz="0 0 1"/>
        <limit effort="10" velocity="10"/>
    </joint>
    <!-- Link shin_grainger_35jc77_7 -->
    <link name="shin_grainger_35jc77_7">
        <inertial>
            <origin xyz="0 0 0" rpy="0 0 0"/>
            <mass value="1e-09"/>
            <inertia ixx="1e-09" ixy="0" ixz="0" iyy="1e-09" iyz="0" izz="1e-09"/>
        </inertial>
        <!-- Part grainger_35jc77_7 -->
        <visual>
            <origin xyz="2.77556e-17 6.93889e-18 0" rpy="1.2326e-32 4.93038e-32 -5.55112e-17"/>
            <geometry>
                <mesh filename="package://catbot_pybullet/meshes/grainger_35jc77.stl"/>
            </geometry>
            <material name="grainger_35jc77_7_material">
                <color rgba="0.203922 0.203922 0.203922 1.0"/>
            </material>
        </visual>
        <collision>
            <origin xyz="2.77556e-17 6.93889e-18 0" rpy="1.2326e-32 4.93038e-32 -5.55112e-17"/>
            <geometry>
                <mesh filename="package://catbot_pybullet/meshes/grainger_35jc77.stl"/>
            </geometry>
        </collision>
    </link>
    <!-- Joint from shin to shin_grainger_35jc77_7 -->
    <joint name="shin_grainger_35jc77_7_fixed" type="fixed">
        <origin xyz="0 0 -0.0091" rpy="-2.01228e-16 1.04083e-16 -3.14159"/>
        <parent link="shin"/>
        <child link="shin_grainger_35jc77_7"/>
        <axis xyz="0 0 1"/>
        <limit effort="10" velocity="10"/>
    </joint>
    <!-- Joint from upper_thigh to shin -->
    <joint name="passive2" type="continuous">
        <origin xyz="-0.224976 -0.00331998 -0.0262503" rpy="-3.14159 2.5947e-16 -1.55425"/>
        <parent link="upper_thigh"/>
        <child link="shin"/>
        <axis xyz="0 0 1"/>
        <limit effort="10" velocity="10"/>
        <joint_properties friction="0.0"/>
    </joint>
    <!-- Link upper_thigh_upper_thigh -->
    <link name="upper_thigh_upper_thigh">
        <inertial>
            <origin xyz="-0.105229 -0.00899999 -3.51128e-18" rpy="0 0 0"/>
            <mass value="0.139251"/>
            <inertia ixx="1.95402e-05" ixy="-9.54797e-11" ixz="2.88727e-06" iyy="0.00060243" iyz="4.60305e-13" izz="0.000594137"/>
        </inertial>
        <!-- Part upper_thigh -->
        <visual>
            <origin xyz="2.77556e-17 -3.38813e-21 0" rpy="0 -5.55112e-17 0"/>
            <geometry>
                <mesh filename="package://catbot_pybullet/meshes/upper_thigh.stl"/>
            </geometry>
            <material name="upper_thigh_material">
                <color rgba="1 1 1 1.0"/>
            </material>
        </visual>
        <collision>
            <origin xyz="2.77556e-17 -3.38813e-21 0" rpy="0 -5.55112e-17 0"/>
            <geometry>
                <mesh filename="package://catbot_pybullet/meshes/upper_thigh.stl"/>
            </geometry>
        </collision>
    </link>
    <!-- Joint from upper_thigh to upper_thigh_upper_thigh -->
    <joint name="upper_thigh_upper_thigh_fixed" type="fixed">
        <origin xyz="5.55112e-17 2.77556e-17 -0.0261503" rpy="-1.5708 2.72047e-16 0.014756"/>
        <parent link="upper_thigh"/>
        <child link="upper_thigh_upper_thigh"/>
        <axis xyz="0 0 1"/>
        <limit effort="10" velocity="10"/>
    </joint>
    <!-- Link upper_thigh_grainger_35jc77_4 -->
    <link name="upper_thigh_grainger_35jc77_4">
        <inertial>
            <origin xyz="0 0 0" rpy="0 0 0"/>
            <mass value="1e-09"/>
            <inertia ixx="1e-09" ixy="0" ixz="0" iyy="1e-09" iyz="0" izz="1e-09"/>
        </inertial>
        <!-- Part grainger_35jc77_4 -->
        <visual>
            <origin xyz="2.77556e-17 0 0" rpy="9.86076e-32 9.86076e-32 0"/>
            <geometry>
                <mesh filename="package://catbot_pybullet/meshes/grainger_35jc77.stl"/>
            </geometry>
            <material name="grainger_35jc77_4_material">
                <color rgba="0.203922 0.203922 0.203922 1.0"/>
            </material>
        </visual>
        <collision>
            <origin xyz="2.77556e-17 0 0" rpy="9.86076e-32 9.86076e-32 0"/>
            <geometry>
                <mesh filename="package://catbot_pybullet/meshes/grainger_35jc77.stl"/>
            </geometry>
        </collision>
    </link>
    <!-- Joint from upper_thigh to upper_thigh_grainger_35jc77_4 -->
    <joint name="upper_thigh_grainger_35jc77_4_fixed" type="fixed">
        <origin xyz="5.55112e-17 2.77556e-17 -0.0247928" rpy="-3.14159 2.72047e-16 0.014756"/>
        <parent link="upper_thigh"/>
        <child link="upper_thigh_grainger_35jc77_4"/>
        <axis xyz="0 0 1"/>
        <limit effort="10" velocity="10"/>
    </joint>
    <!-- Link upper_thigh_grainger_35jc77_5 -->
    <link name="upper_thigh_grainger_35jc77_5">
        <inertial>
            <origin xyz="0 0 0" rpy="0 0 0"/>
            <mass value="1e-09"/>
            <inertia ixx="1e-09" ixy="0" ixz="0" iyy="1e-09" iyz="0" izz="1e-09"/>
        </inertial>
        <!-- Part grainger_35jc77_5 -->
        <visual>
            <origin xyz="0 0 0" rpy="2.46519e-32 -0 0"/>
            <geometry>
                <mesh filename="package://catbot_pybullet/meshes/grainger_35jc77.stl"/>
            </geometry>
            <material name="grainger_35jc77_5_material">
                <color rgba="0.203922 0.203922 0.203922 1.0"/>
            </material>
        </visual>
        <collision>
            <origin xyz="0 0 0" rpy="2.46519e-32 -0 0"/>
            <geometry>
                <mesh filename="package://catbot_pybullet/meshes/grainger_35jc77.stl"/>
            </geometry>
        </collision>
    </link>
    <!-- Joint from upper_thigh to upper_thigh_grainger_35jc77_5 -->
    <joint name="upper_thigh_grainger_35jc77_5_fixed" type="fixed">
        <origin xyz="5.55112e-17 2.77556e-17 -0.00950784" rpy="-3.14159 4.11437e-16 -1.55604"/>
        <parent link="upper_thigh"/>
        <child link="upper_thigh_grainger_35jc77_5"/>
        <axis xyz="0 0 1"/>
        <limit effort="10" velocity="10"/>
    </joint>
    <!-- Joint from lower_to_upper_thigh_connector to upper_thigh -->
    <joint name="passive4" type="revolute">
        <origin xyz="0 0 0.00527485" rpy="3.14159 1.72563e-31 0"/>
        <parent link="lower_to_upper_thigh_connector"/>
        <child link="upper_thigh"/>
        <axis xyz="0 0 1"/>
        <limit effort="10" velocity="10" lower="-0.958899" upper="0.958899"/>
        <joint_properties friction="0.0"/>
    </joint>
    <!-- Link lower_to_upper_thigh_connector_grainger_35jc77_3 -->
    <link name="lower_to_upper_thigh_connector_grainger_35jc77_3">
        <inertial>
            <origin xyz="0 0 0" rpy="0 0 0"/>
            <mass value="1e-09"/>
            <inertia ixx="1e-09" ixy="0" ixz="0" iyy="1e-09" iyz="0" izz="1e-09"/>
        </inertial>
        <!-- Part grainger_35jc77_3 -->
        <visual>
            <origin xyz="5.55112e-17 0 -1.73472e-18" rpy="0 9.86076e-32 0"/>
            <geometry>
                <mesh filename="package://catbot_pybullet/meshes/grainger_35jc77.stl"/>
            </geometry>
            <material name="grainger_35jc77_3_material">
                <color rgba="0.203922 0.203922 0.203922 1.0"/>
            </material>
        </visual>
        <collision>
            <origin xyz="5.55112e-17 0 -1.73472e-18" rpy="0 9.86076e-32 0"/>
            <geometry>
                <mesh filename="package://catbot_pybullet/meshes/grainger_35jc77.stl"/>
            </geometry>
        </collision>
    </link>
    <!-- Joint from lower_to_upper_thigh_connector to lower_to_upper_thigh_connector_grainger_35jc77_3 -->
    <joint name="lower_to_upper_thigh_connector_grainger_35jc77_3_fixed" type="fixed">
        <origin xyz="-0.000995748 -0.060184 0.0224252" rpy="-8.20465e-16 5.49234e-16 3.12684"/>
        <parent link="lower_to_upper_thigh_connector"/>
        <child link="lower_to_upper_thigh_connector_grainger_35jc77_3"/>
        <axis xyz="0 0 1"/>
        <limit effort="10" velocity="10"/>
    </joint>
    <!-- Link lower_to_upper_thigh_connector_d_shaft_lower_motor -->
    <link name="lower_to_upper_thigh_connector_d_shaft_lower_motor">
        <inertial>
            <origin xyz="-2.99252e-17 -7.59981e-05 -0.016046" rpy="0 0 0"/>
            <mass value="0.0183559"/>
            <inertia ixx="1.98047e-06" ixy="-1.10238e-22" ixz="-6.3663e-25" iyy="1.98587e-06" iyz="1.14685e-08" izz="1.96447e-07"/>
        </inertial>
        <!-- Part d_shaft_lower_motor -->
        <visual>
            <origin xyz="0 0 -4.33681e-19" rpy="7.08742e-32 2.01837e-31 0"/>
            <geometry>
                <mesh filename="package://catbot_pybullet/meshes/d_shaft_lower_motor.stl"/>
            </geometry>
            <material name="d_shaft_lower_motor_material">
                <color rgba="0.498039 0.498039 0.498039 1.0"/>
            </material>
        </visual>
        <collision>
            <origin xyz="0 0 -4.33681e-19" rpy="7.08742e-32 2.01837e-31 0"/>
            <geometry>
                <mesh filename="package://catbot_pybullet/meshes/d_shaft_lower_motor.stl"/>
            </geometry>
        </collision>
    </link>
    <!-- Joint from lower_to_upper_thigh_connector to lower_to_upper_thigh_connector_d_shaft_lower_motor -->
    <joint name="lower_to_upper_thigh_connector_d_shaft_lower_motor_fixed" type="fixed">
        <origin xyz="0 0 0.0334109" rpy="5.77848e-17 -4.93476e-16 0"/>
        <parent link="lower_to_upper_thigh_connector"/>
        <child link="lower_to_upper_thigh_connector_d_shaft_lower_motor"/>
        <axis xyz="0 0 1"/>
        <limit effort="10" velocity="10"/>
    </joint>
    <!-- Link lower_to_upper_thigh_connector_pins_3 -->
    <link name="lower_to_upper_thigh_connector_pins_3">
        <inertial>
            <origin xyz="-2.09712e-35 -0.0105 3.77784e-19" rpy="0 0 0"/>
            <mass value="0.0115862"/>
            <inertia ixx="4.8246e-07" ixy="2.37871e-38" ixz="-2.67819e-23" iyy="1.29989e-07" iyz="1.73782e-38" izz="4.8246e-07"/>
        </inertial>
        <!-- Part pins_3 -->
        <visual>
            <origin xyz="0 0 0" rpy="-4.93038e-32 -0 4.93038e-32"/>
            <geometry>
                <mesh filename="package://catbot_pybullet/meshes/pins.stl"/>
            </geometry>
            <material name="pins_3_material">
                <color rgba="0.498039 0.498039 0.498039 1.0"/>
            </material>
        </visual>
        <collision>
            <origin xyz="0 0 0" rpy="-4.93038e-32 -0 4.93038e-32"/>
            <geometry>
                <mesh filename="package://catbot_pybullet/meshes/pins.stl"/>
            </geometry>
        </collision>
    </link>
    <!-- Joint from lower_to_upper_thigh_connector to lower_to_upper_thigh_connector_pins_3 -->
    <joint name="lower_to_upper_thigh_connector_pins_3_fixed" type="fixed">
        <origin xyz="-0.000995748 -0.060184 0.0329252" rpy="1.5708 -6.63175e-16 1.55604"/>
        <parent link="lower_to_upper_thigh_connector"/>
        <child link="lower_to_upper_thigh_connector_pins_3"/>
        <axis xyz="0 0 1"/>
        <limit effort="10" velocity="10"/>
    </joint>
    <!-- Link lower_to_upper_thigh_connector_lower_to_upper_thigh_connector -->
    <link name="lower_to_upper_thigh_connector_lower_to_upper_thigh_connector">
        <inertial>
            <origin xyz="0.0037237 -0.00357124 6.61797e-10" rpy="0 0 0"/>
            <mass value="0.0185659"/>
            <inertia ixx="1.99512e-06" ixy="1.65808e-14" ixz="-4.11269e-13" iyy="1.26869e-05" iyz="-1.75015e-15" izz="1.08503e-05"/>
        </inertial>
        <!-- Part lower_to_upper_thigh_connector -->
        <visual>
            <origin xyz="2.77556e-17 0 0" rpy="1.47911e-31 -0 0"/>
            <geometry>
                <mesh filename="package://catbot_pybullet/meshes/lower_to_upper_thigh_connector.stl"/>
            </geometry>
            <material name="lower_to_upper_thigh_connector_material">
                <color rgba="0.972549 0.529412 0.00392157 1.0"/>
            </material>
        </visual>
        <collision>
            <origin xyz="2.77556e-17 0 0" rpy="1.47911e-31 -0 0"/>
            <geometry>
                <mesh filename="package://catbot_pybullet/meshes/lower_to_upper_thigh_connector.stl"/>
            </geometry>
        </collision>
    </link>
    <!-- Joint from lower_to_upper_thigh_connector to lower_to_upper_thigh_connector_lower_to_upper_thigh_connector -->
    <joint name="lower_to_upper_thigh_connector_lower_to_upper_thigh_connector_fixed" type="fixed">
        <origin xyz="-0.000553083 -0.0301873 0.0259964" rpy="1.5708 -8.58882e-16 1.55604"/>
        <parent link="lower_to_upper_thigh_connector"/>
        <child link="lower_to_upper_thigh_connector_lower_to_upper_thigh_connector"/>
        <axis xyz="0 0 1"/>
        <limit effort="10" velocity="10"/>
    </joint>
    <!-- Joint from part_1 to lower_to_upper_thigh_connector -->
    <joint name="motor2" type="revolute">
        <origin xyz="0.0566635 0.0314074 0.227745" rpy="1.5708 -0.539689 -4.21394e-16"/>
        <parent link="part_1"/>
        <child link="lower_to_upper_thigh_connector"/>
        <axis xyz="0 0 1"/>
        <limit effort="50" velocity="50" lower="-3.141592653589793" upper="3.141592653589793"/>
        <joint_properties friction="0.0"/>
    </joint>
    <!-- Link part_1_part_1 -->
    <link name="part_1_part_1">
        <inertial>
            <origin xyz="0.0987877 0.0358361 0.0125" rpy="0 0 0"/>
            <mass value="0.346789"/>
            <inertia ixx="0.000195825" ixy="0" ixz="4.11394e-36" iyy="0.00104455" iyz="0" izz="0.00120425"/>
        </inertial>
        <!-- Part part_1 -->
        <visual>
            <origin xyz="0 0 0" rpy="0 -1.54113e-32 0"/>
            <geometry>
                <mesh filename="package://catbot_pybullet/meshes/part_1.stl"/>
            </geometry>
            <material name="part_1_material">
                <color rgba="1 1 1 1.0"/>
            </material>
        </visual>
        <collision>
            <origin xyz="0 0 0" rpy="0 -1.54113e-32 0"/>
            <geometry>
                <mesh filename="package://catbot_pybullet/meshes/part_1.stl"/>
            </geometry>
        </collision>
    </link>
    <!-- Joint from part_1 to part_1_part_1 -->
    <joint name="part_1_part_1_fixed" type="fixed">
        <origin xyz="0.0907012 0.0564074 0.263581" rpy="-1.5708 -4.85085e-10 -3.14159"/>
        <parent link="part_1"/>
        <child link="part_1_part_1"/>
        <axis xyz="0 0 1"/>
        <limit effort="10" velocity="10"/>
    </joint>
</robot>
